Workbook
Name Alfamart: Pendukung!$C$21:$C$24
Name Bank: Pendukung!$K$21
Name Beli: Pendukung!$J$21:$J$22
Name Bluebird: Pendukung!$I$21
Name Buka_Puasa: Pendukung!$G$7:$G$9
Name Event_Lomba: Pendukung!$L$21:$L$24
Name Gojek: Pendukung!$H$21
Name Indomaret: Pendukung!$D$21:$D$24
Name Jajan: Pendukung!$C$35:$C$40
Name Makan_Malam: Pendukung!$E$7:$E$13
Name Makan_Siang: Pendukung!$D$7:$D$13
Name N_A: Pendukung!$F$49
Name Pembayaran: Pendukung!$G$49:$G$51
Name Pemeliharaan: Pendukung!$F$21:$F$22
Name Sahur: Pendukung!$F$7:$F$8
Name Sarapan: Pendukung!$C$7:$C$11
Name Sisa: Pendukung!$D$49
Name Superindo: Pendukung!$E$21
Name Telkomsel: Pendukung!$G$21
Name Tokopedia: Pendukung!$M$21:$M$22
Name Transisi: Pendukung!$E$49:$E$50
Name Transisi_NA: Pendukung!$G$57
Name Uang_Bulanan: Pendukung!$C$49:$C$51

Sheet Dashboard
B2: Dashboard Keuangan 3.0
B6: Selamat Datang di Template Keuangan Excel
B8: Template ini bertujuan untuk melacak pengeluaran dan pemasukan yang dilakukan
B10: Selamat Menggunakan
B13: Detail Transaksi | E13: Pengeluaran | H13: Pendapatan | K13: Pendukung
B16: Sheet 'Detail Transaksi' berisi semua transaksi secara detail, mulai dari uang digital dan uang tunai, pengeluaran per minggu, beberapa grafik, dll | E16: Sheet 'Pengeluaran' menangani semua pengeluaran yang dilakukan. Pengeluaran diagi menjadi dua kelompok, Makanan Pokok dan Kebutuhan Lain dan juga pembayaran dipisah antara uang digital dan uang tunai | H16: Sheet 'Pendapatan menangani semua pendapatan yang diterima. Pendapatan tidak memiliki kelompok dan dibagi antara pendapatan tunai dan digital | K16: Sheet 'Pendukung' memberikan dukungan berupa relasi antara Kolom Kategori dan Detail yang terdapat pada sheet Pengeluaran dan Pendapatan serta menyimpan ukuran baris dan kolom masing-masing sheet

Sheet Detail Transaksi
B2: Detail Transaksi
B6: Uang Digital | I6: Pengeluaran per Minggu | P6: Uang tunai | W6: Tanggal Akhir Bulan
I8: Minggu 1 | K8: =SUMIFS(Pengeluaran!$G$9:$G$88, Pengeluaran!$F$9:$F$88, ">="&B48, Pengeluaran!$F$9:$F$88, "<="&E48) + SUMIFS(Pengeluaran!$O$9:$O$88, Pengeluaran!$N$9:$N$88, ">="&B48, Pengeluaran!$N$9:$N$88, "<="&E48) -> 114400 | W8: 45960
B9: Saldo Awal | D9: =SUMIFS(Pendapatan!G6:G15, Pendapatan!E6:E15, "Digital") +SUMIFS(Pendapatan!G6:G15, Pendapatan!D6:D15, "Deposit") -SUMIFS(Pendapatan!G6:G15, Pendapatan!D6:D15, "Tarik Tunai") -> 1500000 | P9: Saldo Awal | R9: =SUMIFS(Pendapatan!G6:G15, Pendapatan!E6:E15, "Tunai") -SUMIFS(Pendapatan!G6:G15, Pendapatan!D6:D15, "Deposit") +SUMIFS(Pendapatan!G6:G15, Pendapatan!D6:D15, "Tarik Tunai") -> 1500000
I10: Minggu 2 | K10: =SUMIFS(Pengeluaran!$G$9:$G$88, Pengeluaran!$F$9:$F$88, ">="&B49, Pengeluaran!$F$9:$F$88, "<="&E49) + SUMIFS(Pengeluaran!$O$9:$O$88, Pengeluaran!$N$9:$N$88, ">="&B49, Pengeluaran!$N$9:$N$88, "<="&E49) -> 71350
W11: Sisa Hari
B12: Saldo Akhir | D12: =D9-SUMIF(Pengeluaran!E9:E88, "Digital", Pengeluaran!G9:G88) -SUMIF(Pengeluaran!M9:M88, "Digital", Pengeluaran!O9:O88) -> 1111150 | I12: Minggu 3 | K12: =SUMIFS(Pengeluaran!$G$9:$G$88, Pengeluaran!$F$9:$F$88, ">="&B50, Pengeluaran!$F$9:$F$88, "<="&E50) + SUMIFS(Pengeluaran!$O$9:$O$88, Pengeluaran!$N$9:$N$88, ">="&B50, Pengeluaran!$N$9:$N$88, "<="&E50) -> 39000 | P12: Saldo Akhir | R12: =R9-SUMIF(Pengeluaran!E9:E88, "Tunai", Pengeluaran!G9:G88) -SUMIF(Pengeluaran!M9:M88, "Tunai", Pengeluaran!O9:O88) -> 1395100
W13: =_xlfn.DAYS(W8, TODAY()) -> 23
I14: Minggu 4 | K14: =SUMIFS(Pengeluaran!$G$9:$G$88, Pengeluaran!$F$9:$F$88, ">="&B51, Pengeluaran!$F$9:$F$88, "<="&E51) + SUMIFS(Pengeluaran!$O$9:$O$88, Pengeluaran!$N$9:$N$88, ">="&B51, Pengeluaran!$N$9:$N$88, "<="&E51) -> 35000
B15: Sisa Bulan Lalu | D15: =SUMIFS(Pendapatan!G6:G15, Pendapatan!C6:C15, "Sisa", Pendapatan!E6:E15, "Digital") -> 1000000 | P15: Sisa Bulan Lalu | R15: =SUMIFS(Pendapatan!G6:G15, Pendapatan!C6:C15, "Sisa", Pendapatan!E6:E15, "Tunai") -> 1000000
I16: Minggu 5 | K16: =SUMIFS(Pengeluaran!$G$9:$G$88, Pengeluaran!$F$9:$F$88, ">="&B52, Pengeluaran!$F$9:$F$88, "<="&E52) + SUMIFS(Pengeluaran!$O$9:$O$88, Pengeluaran!$N$9:$N$88, ">="&B52, Pengeluaran!$N$9:$N$88, "<="&E52) -> 234000 | W16: Rekomendasi Pengeluaran per Hari
W18: =(D9+R9)/DAY(W8) -> 100000
D19: persentase digital | I19: =K8 -> 114400 | K19: minggu 1 | M19: persentase per minggu | R19: persentase tunai
B20: {=SUM(SUMIFS(Pengeluaran!G9:G88, Pengeluaran!C9:C88, {"Sarapan";"Makan_Siang";"Makan_Malam";"Sahur";"Buka_Puasa"}, Pengeluaran!E9:E88, "Digital"))} -> 109500 | D20: makanan digital | I20: =K10 -> 71350 | K20: minggu 2 | P20: {=SUM(SUMIFS(Pengeluaran!G9:G88, Pengeluaran!C9:C88, {"Sarapan";"Makan_Siang";"Makan_Malam";"Sahur";"Buka_Puasa"}, Pengeluaran!E9:E88, "Tunai"))} -> 0 | R20: makanan tunai
B21: =SUMIF(Pengeluaran!M9:M88, "Digital", Pengeluaran!O9:O88) -> 279350 | D21: kebutuhan digital | I21: =K12 -> 39000 | K21: minggu 3 | P21: =SUMIF(Pengeluaran!M9:M88, "Tunai", Pengeluaran!O9:O88) -> 39900 | R21: kebutuhan tunai | W21: Pengeluaran Uang Digital Hari Ini
B22: {=SUM(SUMIFS(Pengeluaran!G9:G88, Pengeluaran!C9:C88, {"Jajan"}, Pengeluaran!E9:E88, "Digital"))} -> 0 | D22: jajan digital | I22: =K14 -> 35000 | K22: minggu 4 | P22: {=SUM(SUMIFS(Pengeluaran!G9:G88, Pengeluaran!C9:C88, {"Jajan"}, Pengeluaran!E9:E88, "Tunai"))} -> 65000 | R22: jajan tunai
B23: =D12 -> 1111150 | D23: sisa uang digital | I23: =K16 -> 234000 | K23: minggu 5 | P23: =R12 -> 1395100 | R23: sisa uang tunai | W23: =SUMIFS(Pengeluaran!G9:G88, Pengeluaran!F9:F88, TODAY(), Pengeluaran!E9:E88, "Digital") + SUMIFS(Pengeluaran!O9:O88, Pengeluaran!N9:N88, TODAY(), Pengeluaran!M9:M88, "Digital") -> 51000
I24: =(D9+R9)-SUM(K8:N17) -> 2506250 | K24: sisa uang digital + tunai
W26: Pengeluaran Uang Tunai Hari Ini
W28: =SUMIFS(Pengeluaran!G9:G88, Pengeluaran!F9:F88, TODAY(), Pengeluaran!E9:E88, "Tunai") + SUMIFS(Pengeluaran!O9:O88, Pengeluaran!N9:N88, TODAY(), Pengeluaran!M9:M88, "Tunai") -> 0
D31: nominal digital | I31: =K8 -> 114400 | K31: minggu 1 | M31: persentase per minggu | R31: nominal tunai | W31: Pengeluaran Total Hari Ini
B32: {=SUM(SUMIFS(Pengeluaran!G9:G88, Pengeluaran!C9:C88, {"Sarapan";"Makan_Siang";"Makan_Malam";"Sahur";"Buka_Puasa"}, Pengeluaran!E9:E88, "Digital"))} -> 109500 | D32: makanan digital | I32: =K10 -> 71350 | K32: minggu 2 | P32: {=SUM(SUMIFS(Pengeluaran!G9:G88, Pengeluaran!C9:C88, {"Sarapan";"Makan_Siang";"Makan_Malam";"Sahur";"Buka_Puasa"}, Pengeluaran!E9:E88, "Tunai"))} -> 0 | R32: makanan tunai
B33: =SUMIF(Pengeluaran!M9:M88, "Digital", Pengeluaran!O9:O88) -> 279350 | D33: kebutuhan digital | I33: =K12 -> 39000 | K33: minggu 3 | P33: =SUMIF(Pengeluaran!M9:M88, "Tunai", Pengeluaran!O9:O88) -> 39900 | R33: kebutuhan tunai | W33: =(W23+W28) -> 51000
B34: {=SUM(SUMIFS(Pengeluaran!G9:G88, Pengeluaran!C9:C88, {"Jajan"}, Pengeluaran!E9:E88, "Digital"))} -> 0 | D34: jajan digital | I34: =K14 -> 35000 | K34: minggu 4 | P34: {=SUM(SUMIFS(Pengeluaran!G9:G88, Pengeluaran!C9:C88, {"Jajan"}, Pengeluaran!E9:E88, "Tunai"))} -> 65000 | R34: jajan tunai
B35: =D12 -> 1111150 | D35: sisa uang digital | I35: =K16 -> 234000 | K35: minggu 5 | P35: =R12 -> 1395100 | R35: sisa uang tunai
B44: Panel Kontrol | I44: Progress Bar Budget | P44: Alokasi Budget
B47: Tanggal Awal | E47: Tanggal Akhir | I47: Makanan Pokok | K47: {=SUM(SUMIFS(Pengeluaran!G9:G68, Pengeluaran!C9:C68, {"Sarapan";"Makan_Siang";"Makan_Malam";"Sahur";"Buka_Puasa"}))} -> 109500 | P47: Makanan Pokok | R47: =(D9+R9)*V47 -> 1200000 | V47: 0.4
B48: 45931 | E48: 45937
B49: 45938 | E49: 45944 | I49: Kebutuhan | K49: =Pengeluaran!P9 -> 319250 | P49: Kebutuhan | R49: =(D9+R9)*V49 -> 1650000 | V49: 0.55
B50: 45945 | E50: 45951
B51: 45952 | E51: 45958 | I51: Jajan | K51: {=SUM(SUMIFS(Pengeluaran!G9:G68, Pengeluaran!C9:C68, {"Jajan"}))} -> 65000 | P51: Jajan | R51: =(D9+R9)*V51 -> 150000 | V51: 0.05
B52: 45959 | E52: 45961

Sheet Pengeluaran
B2: Pengeluaran
B6: Makanan Pokok | J6: Kebutuhan Lain
B8: No | C8: Kategori | D8: Detail | E8: Pembayaran | F8: Tanggal | G8: Harga | H8: Total | J8: No | K8: Kategori | L8: Detail | M8: Pembayaran | N8: Tanggal | O8: Harga | P8: Total
B9: 1 | C9: Sarapan | D9: Warteg | E9: Digital | F9: 45931 | G9: 16500 | H9: =SUM(G9:G68) -> 174500 | J9: 1 | K9: Gojek | L9: Topup Saldo | M9: Digital | N9: 45937 | O9: 51000 | P9: =SUM(O9:O60) -> 319250
B10: 2 | C10: Makan_Siang | D10: Warteg | E10: Digital | F10: 45938 | G10: 17000 | J10: 2 | K10: Bluebird | L10: Bayar | M10: Digital | N10: 45944 | O10: 54350
B11: 3 | C11: Makan_Malam | D11: Nasi Goreng | E11: Digital | F11: 45945 | G11: 16000 | J11: 3 | K11: Beli | L11: Galon | M11: Tunai | N11: 45951 | O11: 23000
B12: 4 | C12: Sahur | D12: Sate | E12: Digital | F12: 45952 | G12: 30000 | J12: 4 | K12: Bank | L12: Admin | M12: Digital | N12: 45958 | O12: 5000
B13: 5 | C13: Jajan | D13: Minuman Manis | E13: Tunai | F13: 45959 | G13: 65000 | J13: 5 | K13: Event_Lomba | L13: CTF | M13: Digital | N13: 45961 | O13: 169000
B14: 6 | C14: Buka_Puasa | D14: Beli | E14: Digital | F14: 45934 | G14: 30000 | J14: 6 | K14: Alfamart | L14: Kebutuhan Dapur | M14: Tunai | N14: 45934 | O14: 16900 | Q14: #AED6F1
B15: 7 | C15: N_A | D15: N/A | E15: N/A | J15: 7 | K15: N_A | L15: N/A | M15: N/A
B16: 8 | C16: N_A | D16: N/A | E16: N/A | J16: 8 | K16: N_A | L16: N/A | M16: N/A
B17: 9 | C17: N_A | D17: N/A | E17: N/A | J17: 9 | K17: N_A | L17: N/A | M17: N/A
B18: 10 | C18: N_A | D18: N/A | E18: N/A | J18: 10 | K18: N_A | L18: N/A | M18: N/A
B19: 11 | C19: N_A | D19: N/A | E19: N/A | J19: 11 | K19: N_A | L19: N/A | M19: N/A
B20: 12 | C20: N_A | D20: N/A | E20: N/A | J20: 12 | K20: N_A | L20: N/A | M20: N/A
B21: 13 | C21: N_A | D21: N/A | E21: N/A | J21: 13 | K21: N_A | L21: N/A | M21: N/A
B22: 14 | C22: N_A | D22: N/A | E22: N/A | J22: 14 | K22: N_A | L22: N/A | M22: N/A
B23: 15 | C23: N_A | D23: N/A | E23: N/A | J23: 15 | K23: N_A | L23: N/A | M23: N/A
B24: 16 | C24: N_A | D24: N/A | E24: N/A | J24: 16 | K24: N_A | L24: N/A | M24: N/A
B25: 17 | C25: N_A | D25: N/A | E25: N/A | J25: 17 | K25: N_A | L25: N/A | M25: N/A
B26: 18 | C26: N_A | D26: N/A | E26: N/A | J26: 18 | K26: N_A | L26: N/A | M26: N/A
... B88: 80 | C88: N_A | D88: N/A | E88: N/A | J88: 80 | K88: N_A | L88: N/A | M88: N/A

Sheet Pendapatan
B2: Pendapatan
B5: No | C5: Kategori | D5: Detail | E5: Pembayaran | F5: Tanggal | G5: Jumlah | H5: Total
B6: 1 | C6: Sisa | D6: Bulan Lalu | E6: Tunai | F6: 45658 | G6: 1000000 | H6: =SUMIFS(G6:G15, C6:C15, "<>Transisi") -> 3000000
B7: 2 | C7: Sisa | D7: Bulan Lalu | E7: Digital | F7: 45658 | G7: 1000000
B8: 3 | C8: Uang_Bulanan | D8: Gaji | E8: Digital | F8: 45658 | G8: 1000000
B9: 4 | C9: Transisi | D9: Tarik Tunai | E9: N/A | F9: 45658 | G9: 500000
B10: 5 | C10: N_A | D10: N/A | E10: N/A
B11: 6 | C11: N_A | D11: N/A | E11: N/A
B12: 7 | C12: N_A | D12: N/A | E12: N/A
B13: 8 | C13: N_A | D13: N/A | E13: N/A
B14: 9 | C14: N_A | D14: N/A | E14: N/A
B15: 10 | C15: N_A | D15: N/A | E15: N/A

Sheet Pendukung
B2: Pendukung
B6: Makanan | C6: Sarapan | D6: Makan Siang | E6: Makan Malam | F6: Sahur | G6: Buka Puasa
C7: Warteg | D7: Warteg | E7: Warteg | F7: Bikin Sendiri | G7: Warteg
C8: Bikin Sendiri | D8: Bikin Sendiri | E8: Bikin Sendiri | F8: Sate | G8: Bikin Sendiri
C9: Nasi Kuning | D9: FKG | E9: Nasi Goreng | G9: Beli
C10: Nasi Uduk | D10: Balsan | E10: Kwetiauw Goreng
C11: Gofood | D11: Gofood | E11: Gofood
D12: Burger Bangor | E12: Burger Bangor
D13: Fried Chicken | E13: Fried Chicken
B16: Warna Kategori | C16: #D35400 | D16: #BA4A00 | E16: #873600 | F16: #B7950B | G16: #943126
B17: Warna Detail | C17: #F5B041 | D17: #EDBB99 | E17: #D68910 | F17: #F7DC6F | G17: #E6B0AA
B18: Nama Warna | C18: Oranye | D18: Merah Jingga | E18: Cokelat | F18: Emas | G18: Merah Marun
B20: Kebutuhan Lain | C20: Alfamart | D20: Indomaret | E20: Superindo | F20: Pemeliharaan | G20: Telkomsel | H20: Gojek | I20: Bluebird | J20: Beli | K20: Bank | L20: Event dan Lomba | M20: Tokopedia
C21: Kebutuhan Dapur | D21: Kebutuhan Dapur | E21: Belanja Mingguan | F21: Cuci Motor | G21: Topup Pulsa | H21: Topup Saldo | I21: Bayar | J21: Galon | K21: Admin | L21: CTF | M21: Kebutuhan Kos
C22: Kebutuhan Kos | D22: Kebutuhan Kos | F22: Laundry | J22: Bensin | L22: Jalan Kaki | M22: Kebutuhan Diri
C23: Kebutuhan Diri | D23: Kebutuhan Diri | L23: Lari
C24: Kebutuhan Mandi | D24: Kebutuhan Mandi | L24: Sepeda
B30: Warna Kategori | C30: #C0392B | D30: #2471A3 | E30: #229954 | F30: #566573 | G30: #E74C3C | H30: #00880C | I30: #2980B9 | J30: #7D3C98 | K30: #1A5276 | L30: #9B59B6 | M30: #03AC0E
B31: Warna Detail | C31: #F5B7B1 | D31: #AED6F1 | E31: #A9DFBF | F31: #CACFD2 | G31: #F1948A | H31: #2980B9 | I31: #A9CCE3 | J31: #D7BDE2 | K31: #85C1E9 | L31: #EBDEF0 | M31: #ABEBC6
B32: Nama Warna | C32: Merah | D32: Biru | E32: Hijau | F32: Abu-abu Arang | G32: Merah Telkom | H32: Hijau Gojek | I32: Biru Bluebird | J32: Ungu | K32: Biru Dongker | L32: Magenta | M32: Hijau Tokped
B34: Jajan dan Keinginan Lainnya | C34: Jajan
C35: Keripik
C36: Minuman Manis
C37: Es Krim
C38: Biskuit
C39: Cokelat
C40: Roti
B44: Warna Kategori | C44: #2471A3
B45: Warna Detail | C45: #AED6F1
B46: Nama Warna | C46: Biru
B48: Pendapatan | C48: Uang Bulanan | D48: Sisa | E48: Transisi | F48: N/A | G48: Pembayaran
C49: Gaji | D49: Bulan Lalu | E49: Deposit | F49: N/A | G49: Tunai
C50: Ortu | E50: Tarik Tunai | G50: Digital
C51: Beasiswa | G51: N/A
G57: N/A
B58: Warna Kategori | C58: #1E8449 | D58: #196F3D | E58: #0E6655 | F58: #797D7F | G58: #2C3E50
B59: Warna Detail | C59: #A2D9CE | D59: #D5F5E3 | E59: #85C1E9 | F59: #F4F6F7 | G59: #AEB6BF
B60: Nama Warna | C60: Hijau Zamrud | D60: Hijau Hutan | E60: Teal | F60: Cokelat Abu | G60: Abu-abu Tua
B62: Nama Sheet | C62: Nama Kolom | D62: Ukuran Tinggi | E62: Ukuran Lebar
B63: Dashboard | C63: Batas | D63: 14.4 | E63: 3
...
