Workbook
Name Alfamart: Pendukung!$C$21:$C$24
Name Bank: Pendukung!$K$21
Name Beli: Pendukung!$J$21:$J$22
Name Bluebird: Pendukung!$I$21
Name Buka_Puasa: Pendukung!$G$7:$G$9
Name Event_Lomba: Pendukung!$L$21:$L$24
Name Gojek: Pendukung!$H$21
Name Indomaret: Pendukung!$D$21:$D$24
Name Jajan: Pendukung!$C$35:$C$40
Name Makan_Malam: Pendukung!$E$7:$E$13
Name Makan_Siang: Pendukung!$D$7:$D$13
Name N_A: Pendukung!$F$49
Name Pembayaran: Pendukung!$G$49:$G$51
Name Pemeliharaan: Pendukung!$F$21:$F$22
Name Sahur: Pendukung!$F$7:$F$8
Name Sarapan: Pendukung!$C$7:$C$11
Name Sisa: Pendukung!$D$49
Name Superindo: Pendukung!$E$21
Name Telkomsel: Pendukung!$G$21
Name Tokopedia: Pendukung!$M$21:$M$22
Name Transisi: Pendukung!$E$49:$E$50
Name Transisi_NA: Pendukung!$G$57
Name Uang_Bulanan: Pendukung!$C$49:$C$51

Sheet Dashboard
B2: Bulan November 2025
B6: Selamat Datang di Template Keuangan Excel
B8: Template ini bertujuan untuk melacak pengeluaran dan pemasukan yang dilakukan
B10: Selamat Menggunakan
B13: Detail Transaksi | E13: Pengeluaran | H13: Pendapatan | K13: Pendukung
B16: Sheet 'Detail Transaksi' berisi semua transaksi secara detail, mulai dari uang digital dan uang tunai, pengeluaran per minggu, beberapa grafik, dll | E16: Sheet 'Pengeluaran' menangani semua pengeluaran yang dilakukan. Pengeluaran diagi menjadi dua kelompok, Makanan Pokok dan Kebutuhan Lain dan juga pembayaran dipisah antara uang digital dan uang tunai | H16: Sheet 'Pendapatan menangani semua pendapatan yang diterima. Pendapatan tidak memiliki kelompok dan dibagi antara pendapatan tunai dan digital | K16: Sheet 'Pendukung' memberikan dukungan berupa relasi antara Kolom Kategori dan Detail yang terdapat pada sheet Pengeluaran dan Pendapatan serta menyimpan ukuran baris dan kolom masing-masing sheet

Sheet Detail Transaksi
B2: Detail Transaksi
B6: Uang Digital | I6: Pengeluaran per Minggu | P6: Uang tunai | W6: Tanggal Akhir Bulan
I8: Minggu 1 | K8: =Kalkulasi!C4 -> 0 | W8: 45991
B9: Saldo Awal | D9: =Kalkulasi!A4 -> 0 | P9: Saldo Awal | R9: =Kalkulasi!B4 -> 0
I10: Minggu 2 | K10: =Kalkulasi!C7 -> 0
W11: Sisa Hari
B12: Saldo Akhir | D12: =Kalkulasi!A7 -> 0 | I12: Minggu 3 | K12: =Kalkulasi!C10 -> 0 | P12: Saldo Akhir | R12: =Kalkulasi!B7 -> 0
W13: =Kalkulasi!D4 -> -1
I14: Minggu 4 | K14: =Kalkulasi!C13 -> 0
B15: Sisa Bulan Lalu | D15: =Kalkulasi!A10 -> 0 | P15: Sisa Bulan Lalu | R15: =Kalkulasi!B10 -> 0
I16: Minggu 5 | K16: =Kalkulasi!C16 -> 0 | W16: Rekomendasi Pengeluaran per Hari
W18: =Kalkulasi!D7 -> 0
D19: persentase digital | I19: =Kalkulasi!C4 -> 0 | K19: minggu 1 | M19: persentase per minggu | R19: persentase tunai
B20: =Kalkulasi!E4 -> 0 | D20: makanan digital | I20: =Kalkulasi!C7 -> 0 | K20: minggu 2 | P20: =Kalkulasi!F4 -> 0 | R20: makanan tunai
B21: =Kalkulasi!E7 -> 0 | D21: kebutuhan digital | I21: =Kalkulasi!C10 -> 0 | K21: minggu 3 | P21: =Kalkulasi!F7 -> 0 | R21: kebutuhan tunai | W21: Pengeluaran Uang Digital Hari Ini
B22: =Kalkulasi!E10 -> 0 | D22: jajan digital | I22: =Kalkulasi!C13 -> 0 | K22: minggu 4 | P22: =Kalkulasi!F10 -> 0 | R22: jajan tunai
B23: =Kalkulasi!E13 -> 0 | D23: sisa uang digital | I23: =Kalkulasi!C16 -> 0 | K23: minggu 5 | P23: =Kalkulasi!F13 -> 0 | R23: sisa uang tunai | W23: =Kalkulasi!D10 -> 0
I24: =Kalkulasi!C19 -> 0 | K24: sisa uang digital + tunai
W26: Pengeluaran Uang Tunai Hari Ini
W28: =Kalkulasi!D13 -> 0
D31: nominal digital | I31: =Kalkulasi!C4 -> 0 | K31: minggu 1 | M31: persentase per minggu | R31: nominal tunai | W31: Pengeluaran Total Hari Ini
B32: =Kalkulasi!E4 -> 0 | D32: makanan digital | I32: =Kalkulasi!C7 -> 0 | K32: minggu 2 | P32: =Kalkulasi!F4 -> 0 | R32: makanan tunai
B33: =Kalkulasi!E7 -> 0 | D33: kebutuhan digital | I33: =Kalkulasi!C10 -> 0 | K33: minggu 3 | P33: =Kalkulasi!F7 -> 0 | R33: kebutuhan tunai | W33: =Kalkulasi!D16 -> 0
B34: =Kalkulasi!E10 -> 0 | D34: jajan digital | I34: =Kalkulasi!C13 -> 0 | K34: minggu 4 | P34: =Kalkulasi!F10 -> 0 | R34: jajan tunai
B35: =Kalkulasi!E13 -> 0 | D35: sisa uang digital | I35: =Kalkulasi!C16 -> 0 | K35: minggu 5 | P35: =Kalkulasi!F13 -> 0 | R35: sisa uang tunai
B44: Panel Kontrol | I44: Progress Bar Budget | P44: Alokasi Budget
B47: Tanggal Awal | E47: Tanggal Akhir | I47: Makanan Pokok | K47: =Kalkulasi!H4 -> 0 | P47: Makanan Pokok | R47: =Kalkulasi!J4 -> 0 | V47: 0.4
B48: 45962 | E48: 45968
B49: 45969 | E49: 45975 | I49: Kebutuhan | K49: =Kalkulasi!H7 -> 0 | P49: Kebutuhan | R49: =Kalkulasi!J7 -> 0 | V49: 0.55
B50: 45976 | E50: 45982
B51: 45983 | E51: 45989 | I51: Jajan | K51: =Kalkulasi!H10 -> 0 | P51: Jajan | R51: =Kalkulasi!J10 -> 0 | V51: 0.05
B52: 45990 | E52: 45991

Sheet Pengeluaran
B2: Pengeluaran
B6: Makanan Pokok | J6: Kebutuhan Lain
B8: No | C8: Kategori | D8: Detail | E8: Pembayaran | F8: Tanggal | G8: Harga | H8: Total | J8: No | K8: Kategori | L8: Detail | M8: Pembayaran | N8: Tanggal | O8: Harga | P8: Total
B9: 1 | C9: N_A | D9: N/A | E9: N/A | H9: =Kalkulasi!A23 -> 0 | J9: 1 | K9: N_A | L9: N/A | M9: N/A | P9: =Kalkulasi!A26 -> 0
B10: 2 | C10: N_A | D10: N/A | E10: N/A | J10: 2 | K10: N_A | L10: N/A | M10: N/A
B11: 3 | C11: N_A | D11: N/A | E11: N/A | J11: 3 | K11: N_A | L11: N/A | M11: N/A
B12: 4 | C12: N_A | D12: N/A | E12: N/A | J12: 4 | K12: N_A | L12: N/A | M12: N/A
B13: 5 | C13: N_A | D13: N/A | E13: N/A | J13: 5 | K13: N_A | L13: N/A | M13: N/A
B14: 6 | C14: N_A | D14: N/A | E14: N/A | J14: 6 | K14: N_A | L14: N/A | M14: N/A
B15: 7 | C15: N_A | D15: N/A | E15: N/A | J15: 7 | K15: N_A | L15: N/A | M15: N/A
B16: 8 | C16: N_A | D16: N/A | E16: N/A | J16: 8 | K16: N_A | L16: N/A | M16: N/A
B17: 9 | C17: N_A | D17: N/A | E17: N/A | J17: 9 | K17: N_A | L17: N/A | M17: N/A
B18: 10 | C18: N_A | D18: N/A | E18: N/A | J18: 10 | K18: N_A | L18: N/A | M18: N/A
B19: 11 | C19: N_A | D19: N/A | E19: N/A | J19: 11 | K19: N_A | L19: N/A | M19: N/A
B20: 12 | C20: N_A | D20: N/A | E20: N/A | J20: 12 | K20: N_A | L20: N/A | M20: N/A
B21: 13 | C21: N_A | D21: N/A | E21: N/A | J21: 13 | K21: N_A | L21: N/A | M21: N/A
... B88: 80 | C88: N_A | D88: N/A | E88: N/A | J88: 80 | K88: N_A | L88: N/A | M88: N/A
B89: 81 | C89: N_A | D89: N/A | E89: N/A
B90: 82 | C90: N_A | D90: N/A | E90: N/A
B91: 83 | C91: N_A | D91: N/A | E91: N/A
B92: 84 | C92: N_A | D92: N/A | E92: N/A
B93: 85 | C93: N_A | D93: N/A | E93: N/A
B94: 86 | C94: N_A | D94: N/A | E94: N/A
B95: 87 | C95: N_A | D95: N/A | E95: N/A
B96: 88 | C96: N_A | D96: N/A | E96: N/A
B97: 89 | C97: N_A | D97: N/A | E97: N/A
B98: 90 | C98: N_A | D98: N/A | E98: N/A
B99: 91 | C99: N_A | D99: N/A | E99: N/A
B100: 92 | C100: N_A | D100: N/A | E100: N/A
... B129: 121 | C129: N_A | D129: N/A | E129: N/A

Sheet Pendapatan
B2: Pendapatan
B5: No | C5: Kategori | D5: Detail | E5: Pembayaran | F5: Tanggal | G5: Jumlah | H5: Total
B6: 1 | C6: N_A | D6: N/A | E6: N/A | H6: =Kalkulasi!A30 -> 0
B7: 2 | C7: N_A | D7: N/A | E7: N/A
B8: 3 | C8: N_A | D8: N/A | E8: N/A
B9: 4 | C9: N_A | D9: N/A | E9: N/A
B10: 5 | C10: N_A | D10: N/A | E10: N/A
B11: 6 | C11: N_A | D11: N/A | E11: N/A
B12: 7 | C12: N_A | D12: N/A | E12: N/A
B13: 8 | C13: N_A | D13: N/A | E13: N/A
B14: 9 | C14: N_A | D14: N/A | E14: N/A
B15: 10 | C15: N_A | D15: N/A | E15: N/A

Sheet Akhir Bulan
B2: Kalender | J2: Tabungan
B6: Sabtu | C6: Minggu | D6: Senin | E6: Selasa | F6: Rabu | G6: Kamis | H6: Jumat | J6: Tabungan Awal | L6: Tabungan Akhir | N6: Perubahan | P6: Persentase Perubahan | R6: Hasil
B9: 45962 | C9: 45963 | D9: 45964 | E9: 45965 | F9: 45966 | G9: 45967 | H9: 45968 | J9: =Kalkulasi!H35 -> 0 | L9: =Kalkulasi!I35 -> 0 | N9: =Kalkulasi!J35 -> 0 | P9: =Kalkulasi!K35 -> 0 | R9: =Kalkulasi!H38 -> Tetap 😐
B10: =Kalkulasi!A35 -> 0 | C10: =Kalkulasi!B35 -> 0 | D10: =Kalkulasi!C35 -> 0 | E10: =Kalkulasi!D35 -> 0 | F10: =Kalkulasi!E35 -> 0 | G10: =Kalkulasi!F35 -> 0 | H10: =Kalkulasi!G35 -> 0
B13: 45969 | C13: 45970 | D13: 45971 | E13: 45972 | F13: 45973 | G13: 45974 | H13: 45975 | J13: Pemasukan | L13: Pengeluaran | N13: Sisa Uang (Arus Kas Bersih) | P13: Persentase Arus Kas | R13: Hasil
B14: =Kalkulasi!A38 -> 0 | C14: =Kalkulasi!B38 -> 0 | D14: =Kalkulasi!C38 -> 0 | E14: =Kalkulasi!D38 -> 0 | F14: =Kalkulasi!E38 -> 0 | G14: =Kalkulasi!F38 -> 0 | H14: =Kalkulasi!G38 -> 0
J16: =Kalkulasi!H41 -> 0 | L16: =Kalkulasi!I41 -> 0 | N16: =Kalkulasi!J41 -> 0 | P16: =Kalkulasi!K41 -> 0 | R16: =Kalkulasi!H44 -> Positif ✅
B17: 45976 | C17: 45977 | D17: 45978 | E17: 45979 | F17: 45980 | G17: 45981 | H17: 45982
B18: =Kalkulasi!A41 -> 0 | C18: =Kalkulasi!B41 -> 0 | D18: =Kalkulasi!C41 -> 0 | E18: =Kalkulasi!D41 -> 0 | F18: =Kalkulasi!E41 -> 0 | G18: =Kalkulasi!F41 -> 0 | H18: =Kalkulasi!G41 -> 0
B21: 45983 | C21: 45984 | D21: 45985 | E21: 45986 | F21: 45987 | G21: 45988 | H21: 45989
B22: =Kalkulasi!A44 -> 0 | C22: =Kalkulasi!B44 -> 0 | D22: =Kalkulasi!C44 -> 0 | E22: =Kalkulasi!D44 -> 0 | F22: =Kalkulasi!E44 -> 0 | G22: =Kalkulasi!F44 -> 0 | H22: =Kalkulasi!G44 -> 0
B25: 45990 | C25: 45991
B26: =Kalkulasi!A47 -> 0 | C26: =Kalkulasi!B47 -> 0
B32: Sarapan | D32: Jumlah | E32: Makan_Siang | G32: Jumlah | H32: Makan_Malam | J32: Jumlah | K32: Jajan | M32: Jumlah | N32: Sahur | P32: Jumlah | Q32: Buka_Puasa | S32: Jumlah
B34: Warteg | C34: =Kalkulasi!B50 -> 0 | D34: =COUNTIFS(Pengeluaran!$C$9:$C$129, 'Akhir Bulan'!$B$32, Pengeluaran!$D$9:$D$129, 'Akhir Bulan'!B34) -> 0 | E34: Warteg | F34: =Kalkulasi!D50 -> 0 | G34: =COUNTIFS(Pengeluaran!$C$9:$C$129, 'Akhir Bulan'!$E$32, Pengeluaran!$D$9:$D$129, 'Akhir Bulan'!E34) -> 0 | H34: Warteg | I34: =Kalkulasi!F50 -> 0 | J34: =COUNTIFS(Pengeluaran!$C$9:$C$129, 'Akhir Bulan'!$H$32, Pengeluaran!$D$9:$D$129, 'Akhir Bulan'!H34) -> 0 | K34: Keripik | L34: =Kalkulasi!H50 -> 0 | M34: =COUNTIFS(Pengeluaran!$C$9:$C$129, 'Akhir Bulan'!$K$32, Pengeluaran!$D$9:$D$129, 'Akhir Bulan'!K34) -> 0 | N34: Bikin Sendiri | O34: =Kalkulasi!J50 -> 0 | P34: =COUNTIFS(Pengeluaran!$C$9:$C$129, 'Akhir Bulan'!$N$32, Pengeluaran!$D$9:$D$129, 'Akhir Bulan'!N34) -> 0 | Q34: Warteg | R34: =Kalkulasi!L50 -> 0 | S34: =COUNTIFS(Pengeluaran!$C$9:$C$129, 'Akhir Bulan'!$Q$32, Pengeluaran!$D$9:$D$129, 'Akhir Bulan'!Q34) -> 0
B36: Bikin Sendiri | C36: =Kalkulasi!B51 -> 0 | D36: =COUNTIFS(Pengeluaran!$C$9:$C$129, 'Akhir Bulan'!$B$32, Pengeluaran!$D$9:$D$129, 'Akhir Bulan'!B36) -> 0 | E36: Bikin Sendiri | F36: =Kalkulasi!D51 -> 0 | G36: =COUNTIFS(Pengeluaran!$C$9:$C$129, 'Akhir Bulan'!$E$32, Pengeluaran!$D$9:$D$129, 'Akhir Bulan'!E36) -> 0 | H36: Bikin Sendiri | I36: =Kalkulasi!F51 -> 0 | J36: =COUNTIFS(Pengeluaran!$C$9:$C$129, 'Akhir Bulan'!$H$32, Pengeluaran!$D$9:$D$129, 'Akhir Bulan'!H36) -> 0 | K36: Minuman Manis | L36: =Kalkulasi!H51 -> 0 | M36: =COUNTIFS(Pengeluaran!$C$9:$C$129, 'Akhir Bulan'!$K$32, Pengeluaran!$D$9:$D$129, 'Akhir Bulan'!K36) -> 0 | N36: Sate | O36: =Kalkulasi!J51 -> 0 | P36: =COUNTIFS(Pengeluaran!$C$9:$C$129, 'Akhir Bulan'!$N$32, Pengeluaran!$D$9:$D$129, 'Akhir Bulan'!N36) -> 0 | Q36: Bikin Sendiri | R36: =Kalkulasi!L51 -> 0 | S36: =COUNTIFS(Pengeluaran!$C$9:$C$129, 'Akhir Bulan'!$Q$32, Pengeluaran!$D$9:$D$129, 'Akhir Bulan'!Q36) -> 0
B38: Nasi Kuning | C38: =Kalkulasi!B52 -> 0 | D38: =COUNTIFS(Pengeluaran!$C$9:$C$129, 'Akhir Bulan'!$B$32, Pengeluaran!$D$9:$D$129, 'Akhir Bulan'!B38) -> 0 | E38: FKG | F38: =Kalkulasi!D52 -> 0 | G38: =COUNTIFS(Pengeluaran!$C$9:$C$129, 'Akhir Bulan'!$E$32, Pengeluaran!$D$9:$D$129, 'Akhir Bulan'!E38) -> 0 | H38: Nasi Goreng | I38: =Kalkulasi!F52 -> 0 | J38: =COUNTIFS(Pengeluaran!$C$9:$C$129, 'Akhir Bulan'!$H$32, Pengeluaran!$D$9:$D$129, 'Akhir Bulan'!H38) -> 0 | K38: Es Krim | L38: =Kalkulasi!H52 -> 0 | M38: =COUNTIFS(Pengeluaran!$C$9:$C$129, 'Akhir Bulan'!$K$32, Pengeluaran!$D$9:$D$129, 'Akhir Bulan'!K38) -> 0 | Q38: Beli | R38: =Kalkulasi!L52 -> 0 | S38: =COUNTIFS(Pengeluaran!$C$9:$C$129, 'Akhir Bulan'!$Q$32, Pengeluaran!$D$9:$D$129, 'Akhir Bulan'!Q38) -> 0
B40: Nasi Uduk | C40: =Kalkulasi!B53 -> 0 | D40: =COUNTIFS(Pengeluaran!$C$9:$C$129, 'Akhir Bulan'!$B$32, Pengeluaran!$D$9:$D$129, 'Akhir Bulan'!B40) -> 0 | E40: Balsan | F40: =Kalkulasi!D53 -> 0 | G40: =COUNTIFS(Pengeluaran!$C$9:$C$129, 'Akhir Bulan'!$E$32, Pengeluaran!$D$9:$D$129, 'Akhir Bulan'!E40) -> 0 | H40: Kwetiauw Goreng | I40: =Kalkulasi!F53 -> 0 | J40: =COUNTIFS(Pengeluaran!$C$9:$C$129, 'Akhir Bulan'!$H$32, Pengeluaran!$D$9:$D$129, 'Akhir Bulan'!H40) -> 0 | K40: Biskuit | L40: =Kalkulasi!H53 -> 0 | M40: =COUNTIFS(Pengeluaran!$C$9:$C$129, 'Akhir Bulan'!$K$32, Pengeluaran!$D$9:$D$129, 'Akhir Bulan'!K40) -> 0
B42: Gofood | C42: =Kalkulasi!B54 -> 0 | D42: =COUNTIFS(Pengeluaran!$C$9:$C$129, 'Akhir Bulan'!$B$32, Pengeluaran!$D$9:$D$129, 'Akhir Bulan'!B42) -> 0 | E42: Gofood | F42: =Kalkulasi!D54 -> 0 | G42: =COUNTIFS(Pengeluaran!$C$9:$C$129, 'Akhir Bulan'!$E$32, Pengeluaran!$D$9:$D$129, 'Akhir Bulan'!E42) -> 0 | H42: Gofood | I42: =Kalkulasi!F54 -> 0 | J42: =COUNTIFS(Pengeluaran!$C$9:$C$129, 'Akhir Bulan'!$H$32, Pengeluaran!$D$9:$D$129, 'Akhir Bulan'!H42) -> 0 | K42: Cokelat | L42: =Kalkulasi!H54 -> 0 | M42: =COUNTIFS(Pengeluaran!$C$9:$C$129, 'Akhir Bulan'!$K$32, Pengeluaran!$D$9:$D$129, 'Akhir Bulan'!K42) -> 0
E44: Burger Bangor | F44: =Kalkulasi!D55 -> 0 | G44: =COUNTIFS(Pengeluaran!$C$9:$C$129, 'Akhir Bulan'!$E$32, Pengeluaran!$D$9:$D$129, 'Akhir Bulan'!E44) -> 0 | H44: Burger Bangor | I44: =Kalkulasi!F55 -> 0 | J44: =COUNTIFS(Pengeluaran!$C$9:$C$129, 'Akhir Bulan'!$H$32, Pengeluaran!$D$9:$D$129, 'Akhir Bulan'!H44) -> 0 | K44: Roti | L44: =Kalkulasi!H55 -> 0 | M44: =COUNTIFS(Pengeluaran!$C$9:$C$129, 'Akhir Bulan'!$K$32, Pengeluaran!$D$9:$D$129, 'Akhir Bulan'!K44) -> 0
E46: Fried Chicken | F46: =Kalkulasi!D56 -> 0 | G46: =COUNTIFS(Pengeluaran!$C$9:$C$129, 'Akhir Bulan'!$E$32, Pengeluaran!$D$9:$D$129, 'Akhir Bulan'!E46) -> 0 | H46: Fried Chicken | I46: =Kalkulasi!F56 -> 0 | J46: =COUNTIFS(Pengeluaran!$C$9:$C$129, 'Akhir Bulan'!$H$32, Pengeluaran!$D$9:$D$129, 'Akhir Bulan'!H46) -> 0
E48: Nasi Kuning | F48: =Kalkulasi!D57 -> 0 | G48: =COUNTIFS(Pengeluaran!$C$9:$C$129, 'Akhir Bulan'!$E$32, Pengeluaran!$D$9:$D$129, 'Akhir Bulan'!E48) -> 0 | H48: Balsan | I48: =Kalkulasi!F57 -> 0 | J48: =COUNTIFS(Pengeluaran!$C$9:$C$129, 'Akhir Bulan'!$H$32, Pengeluaran!$D$9:$D$129, 'Akhir Bulan'!H48) -> 0
B51: Kebutuhan | D51: Jumlah | E51: Kebutuhan | G51: Jumlah | H51: Kebutuhan | J51: Jumlah | K51: Kebutuhan | M51: Jumlah
B53: Kebutuhan Dapur | C53: =Kalkulasi!B60 -> 0 | D53: =COUNTIFS(Pengeluaran!$L$9:$L$88, 'Akhir Bulan'!B53) -> 0 | E53: Cuci Motor | F53: =Kalkulasi!D60 -> 0 | G53: =COUNTIFS(Pengeluaran!$L$9:$L$88, 'Akhir Bulan'!E53) -> 0 | H53: Bayar Argo | I53: =Kalkulasi!F60 -> 0 | J53: =COUNTIFS(Pengeluaran!$L$9:$L$88, 'Akhir Bulan'!H53) -> 0 | K53: CTF | L53: =Kalkulasi!H60 -> 0 | M53: =COUNTIFS(Pengeluaran!$L$9:$L$88, 'Akhir Bulan'!K53) -> 0
B55: Kebutuhan Kos | C55: =Kalkulasi!B61 -> 0 | D55: =COUNTIFS(Pengeluaran!$L$9:$L$88, 'Akhir Bulan'!B55) -> 0 | E55: Laundry | F55: =Kalkulasi!D61 -> 0 | G55: =COUNTIFS(Pengeluaran!$L$9:$L$88, 'Akhir Bulan'!E55) -> 0 | H55: Galon | I55: =Kalkulasi!F61 -> 0 | J55: =COUNTIFS(Pengeluaran!$L$9:$L$88, 'Akhir Bulan'!H55) -> 0 | K55: Jalan Kaki | L55: =Kalkulasi!H61 -> 0 | M55: =COUNTIFS(Pengeluaran!$L$9:$L$88, 'Akhir Bulan'!K55) -> 0
B57: Kebutuhan Diri | C57: =Kalkulasi!B62 -> 0 | D57: =COUNTIFS(Pengeluaran!$L$9:$L$88, 'Akhir Bulan'!B57) -> 0 | E57: Topup Pulsa | F57: =Kalkulasi!D62 -> 0 | G57: =COUNTIFS(Pengeluaran!$L$9:$L$88, 'Akhir Bulan'!E57) -> 0 | H57: Bensin | I57: =Kalkulasi!F62 -> 0 | J57: =COUNTIFS(Pengeluaran!$L$9:$L$88, 'Akhir Bulan'!H57) -> 0 | K57: Lari | L57: =Kalkulasi!H62 -> 0 | M57: =COUNTIFS(Pengeluaran!$L$9:$L$88, 'Akhir Bulan'!K57) -> 0
B59: Kebutuhan Mandi | C59: =Kalkulasi!B63 -> 0 | D59: =COUNTIFS(Pengeluaran!$L$9:$L$88, 'Akhir Bulan'!B59) -> 0 | E59: Topup Gopay | F59: =Kalkulasi!D63 -> 0 | G59: =COUNTIFS(Pengeluaran!$L$9:$L$88, 'Akhir Bulan'!E59) -> 0 | H59: Admin | I59: =Kalkulasi!F63 -> 0 | J59: =COUNTIFS(Pengeluaran!$L$9:$L$88, 'Akhir Bulan'!H59) -> 0 | K59: Sepeda | L59: =Kalkulasi!H63 -> 0 | M59: =COUNTIFS(Pengeluaran!$L$9:$L$88, 'Akhir Bulan'!K59) -> 0
B61: Belanja Mingguan | C61: =Kalkulasi!B64 -> 0 | D61: =COUNTIFS(Pengeluaran!$L$9:$L$88, 'Akhir Bulan'!B61) -> 0 | E61: Infaq | F61: =Kalkulasi!D64 -> 0 | G61: =COUNTIFS(Pengeluaran!$L$9:$L$88, 'Akhir Bulan'!E61) -> 0

Sheet Pendukung
B2: Pendukung
B6: Makanan | C6: Sarapan | D6: Makan Siang | E6: Makan Malam | F6: Sahur | G6: Buka Puasa
C7: Warteg | D7: Warteg | E7: Warteg | F7: Bikin Sendiri | G7: Warteg
C8: Bikin Sendiri | D8: Bikin Sendiri | E8: Bikin Sendiri | F8: Sate | G8: Bikin Sendiri
C9: Nasi Kuning | D9: FKG | E9: Nasi Goreng | G9: Beli
C10: Nasi Uduk | D10: Balsan | E10: Kwetiauw Goreng
C11: Gofood | D11: Gofood | E11: Gofood
D12: Burger Bangor | E12: Burger Bangor
D13: Fried Chicken | E13: Fried Chicken
B16: Warna Kategori | C16: #D35400 | D16: #BA4A00 | E16: #873600 | F16: #B7950B | G16: #943126
B17: Warna Detail | C17: #F5B041 | D17: #EDBB99 | E17: #D68910 | F17: #F7DC6F | G17: #E6B0AA
B18: Nama Warna | C18: Oranye | D18: Merah Jingga | E18: Cokelat | F18: Emas | G18: Merah Marun
B20: Kebutuhan Lain | C20: Alfamart | D20: Indomaret | E20: Superindo | F20: Pemeliharaan | G20: Telkomsel | H20: Gojek | I20: Bluebird | J20: Beli | K20: Bank | L20: Event dan Lomba | M20: Tokopedia
C21: Kebutuhan Dapur | D21: Kebutuhan Dapur | E21: Belanja Mingguan | F21: Cuci Motor | G21: Topup Pulsa | H21: Topup Gopay | I21: Bayar Argo | J21: Galon | K21: Admin | L21: CTF | M21: Kebutuhan Kos
C22: Kebutuhan Kos | D22: Kebutuhan Kos | F22: Laundry | J22: Bensin | L22: Jalan Kaki | M22: Kebutuhan Diri
C23: Kebutuhan Diri | D23: Kebutuhan Diri | L23: Lari
C24: Kebutuhan Mandi | D24: Kebutuhan Mandi | L24: Sepeda
B30: Warna Kategori | C30: #C0392B | D30: #2471A3 | E30: #229954 | F30: #566573 | G30: #E74C3C | H30: #00880C | I30: #2980B9 | J30: #7D3C98 | K30: #1A5276 | L30: #9B59B6 | M30: #03AC0E
B31: Warna Detail | C31: #F5B7B1 | D31: #AED6F1 | E31: #A9DFBF | F31: #CACFD2 | G31: #F1948A | H31: #2980B9 | I31: #A9CCE3 | J31: #D7BDE2 | K31: #85C1E9 | L31: #EBDEF0 | M31: #ABEBC6
B32: Nama Warna | C32: Merah | D32: Biru | E32: Hijau | F32: Abu-abu Arang | G32: Merah Telkom | H32: Hijau Gojek | I32: Biru Bluebird | J32: Ungu | K32: Biru Dongker | L32: Magenta | M32: Hijau Tokped
B34: Jajan dan Keinginan Lainnya | C34: Jajan
C35: Keripik
C36: Minuman Manis
C37: Es Krim
C38: Biskuit
C39: Cokelat
C40: Roti
B44: Warna Kategori | C44: #2471A3
B45: Warna Detail | C45: #AED6F1
B46: Nama Warna | C46: Biru
B48: Pendapatan | C48: Uang Bulanan | D48: Sisa | E48: Transisi | F48: N/A | G48: Pembayaran
C49: Gaji | D49: Bulan Lalu | E49: Deposit | F49: N/A | G49: Tunai
C50: Ortu | E50: Tarik Tunai | G50: Digital
C51: Beasiswa | G51: N/A
G57: N/A
B58: Warna Kategori | C58: #1E8449 | D58: #196F3D | E58: #0E6655 | F58: #797D7F | G58: #2C3E50
B59: Warna Detail | C59: #A2D9CE | D59: #D5F5E3 | E59: #85C1E9 | F59: #F4F6F7 | G59: #AEB6BF
B60: Nama Warna | C60: Hijau Zamrud | D60: Hijau Hutan | E60: Teal | F60: Cokelat Abu | G60: Abu-abu Tua
B62: Nama Sheet | C62: Nama Kolom | D62: Ukuran Tinggi | E62: Ukuran Lebar
B63: Dashboard | C63: Batas | D63: 14.4 | E63: 3
...

Sheet Kalkulasi
A1: detail transaksi
E2: persen/nominal digital | F2: persen/nominal tunai
A3: saldo awal digital | B3: saldo awal tunai | C3: pengeluaran minggu 1 | D3: sisa hari | E3: makanan digital | F3: makanan tunai | H3: progress bar makanan | J3: alokasi makanan
A4: =SUMIFS(Pendapatan!G6:G15, Pendapatan!E6:E15, "Digital")+SUMIFS(Pendapatan!G6:G15, Pendapatan!D6:D15, "Deposit")-SUMIFS(Pendapatan!G6:G15, Pendapatan!D6:D15, "Tarik Tunai") -> 0 | B4: =SUMIFS(Pendapatan!G6:G15, Pendapatan!E6:E15, "Tunai") -SUMIFS(Pendapatan!G6:G15, Pendapatan!D6:D15, "Deposit") +SUMIFS(Pendapatan!G6:G15, Pendapatan!D6:D15, "Tarik Tunai") -> 0 | C4: =SUMIFS(Pengeluaran!$G$9:$G$129, Pengeluaran!$F$9:$F$129, ">="&'Detail Transaksi'!B48, Pengeluaran!$F$9:$F$129, "<="&'Detail Transaksi'!E48) + SUMIFS(Pengeluaran!$O$9:$O$88, Pengeluaran!$N$9:$N$88, ">="&'Detail Transaksi'!B48, Pengeluaran!$N$9:$N$88, "<="&'Detail Transaksi'!E48) -> 0 | D4: =_xlfn.DAYS('Detail Transaksi'!W8, TODAY()) -> -1 | E4: {=SUM(SUMIFS(Pengeluaran!G9:G129, Pengeluaran!C9:C129, {"Sarapan";"Makan_Siang";"Makan_Malam";"Sahur";"Buka_Puasa"}, Pengeluaran!E9:E129, "Digital"))} -> 0 | F4: {=SUM(SUMIFS(Pengeluaran!G9:G129, Pengeluaran!C9:C129, {"Sarapan";"Makan_Siang";"Makan_Malam";"Sahur";"Buka_Puasa"}, Pengeluaran!E9:E129, "Tunai"))} -> 0 | H4: {=SUM(SUMIFS(Pengeluaran!G9:G129, Pengeluaran!C9:C129, {"Sarapan";"Makan_Siang";"Makan_Malam";"Sahur";"Buka_Puasa"}))} -> 0 | J4: =('Detail Transaksi'!D9+'Detail Transaksi'!R9)*'Detail Transaksi'!V47 -> 0
A6: saldo akhir digital | B6: saldo akhir tunai | C6: pengeluaran minggu 2 | D6: rekomendasi pengeluaran | E6: kebutuhan digital | F6: kebutuhan tunai | H6: progress bar kebutuhan | J6: alokasi kebutuhan
A7: ='Detail Transaksi'!D9-SUMIF(Pengeluaran!E9:E129, "Digital", Pengeluaran!G9:G129) -SUMIF(Pengeluaran!M9:M88, "Digital", Pengeluaran!O9:O88) -> 0 | B7: ='Detail Transaksi'!R9-SUMIF(Pengeluaran!E9:E129, "Tunai", Pengeluaran!G9:G129) -SUMIF(Pengeluaran!M9:M88, "Tunai", Pengeluaran!O9:O88) -> 0 | C7: =SUMIFS(Pengeluaran!$G$9:$G$129, Pengeluaran!$F$9:$F$129, ">="&'Detail Transaksi'!B49, Pengeluaran!$F$9:$F$129, "<="&'Detail Transaksi'!E49) + SUMIFS(Pengeluaran!$O$9:$O$88, Pengeluaran!$N$9:$N$88, ">="&'Detail Transaksi'!B49, Pengeluaran!$N$9:$N$88, "<="&'Detail Transaksi'!E49) -> 0 | D7: =('Detail Transaksi'!D9+'Detail Transaksi'!R9)/DAY('Detail Transaksi'!W8) -> 0 | E7: =SUMIF(Pengeluaran!M9:M88, "Digital", Pengeluaran!O9:O88) -> 0 | F7: =SUMIF(Pengeluaran!M9:M88, "Tunai", Pengeluaran!O9:O88) -> 0 | H7: =Pengeluaran!P9 -> 0 | J7: =('Detail Transaksi'!D9+'Detail Transaksi'!R9)*'Detail Transaksi'!V49 -> 0
A9: sisa uang bulan lalu digital | B9: sisa uang bulan lalu tunai | C9: pengeluaran minggu 3 | D9: pengeluaran digital hari ini | E9: jajan digital | F9: jajan tunai | H9: progress bar jajan | J9: alokasi jajan
A10: =SUMIFS(Pendapatan!G6:G15, Pendapatan!C6:C15, "Sisa", Pendapatan!E6:E15, "Digital") -> 0 | B10: =SUMIFS(Pendapatan!G6:G15, Pendapatan!C6:C15, "Sisa", Pendapatan!E6:E15, "Tunai") -> 0 | C10: =SUMIFS(Pengeluaran!$G$9:$G$129, Pengeluaran!$F$9:$F$129, ">="&'Detail Transaksi'!B50, Pengeluaran!$F$9:$F$129, "<="&'Detail Transaksi'!E50) + SUMIFS(Pengeluaran!$O$9:$O$88, Pengeluaran!$N$9:$N$88, ">="&'Detail Transaksi'!B50, Pengeluaran!$N$9:$N$88, "<="&'Detail Transaksi'!E50) -> 0 | D10: =SUMIFS(Pengeluaran!G9:G129, Pengeluaran!F9:F129, TODAY(), Pengeluaran!E9:E129, "Digital") + SUMIFS(Pengeluaran!O9:O88, Pengeluaran!N9:N88, TODAY(), Pengeluaran!M9:M88, "Digital") -> 0 | E10: {=SUM(SUMIFS(Pengeluaran!G9:G129, Pengeluaran!C9:C129, {"Jajan"}, Pengeluaran!E9:E129, "Digital"))} -> 0 | F10: {=SUM(SUMIFS(Pengeluaran!G9:G129, Pengeluaran!C9:C129, {"Jajan"}, Pengeluaran!E9:E129, "Tunai"))} -> 0 | H10: {=SUM(SUMIFS(Pengeluaran!G9:G129, Pengeluaran!C9:C129, {"Jajan"}))} -> 0 | J10: =('Detail Transaksi'!D9+'Detail Transaksi'!R9)*'Detail Transaksi'!V51 -> 0
C12: pengeluaran minggu 4 | D12: pengeluaran tunai hari ini | E12: sisa uang digital | F12: sisa uang tunai
C13: =SUMIFS(Pengeluaran!$G$9:$G$129, Pengeluaran!$F$9:$F$129, ">="&'Detail Transaksi'!B51, Pengeluaran!$F$9:$F$129, "<="&'Detail Transaksi'!E51) + SUMIFS(Pengeluaran!$O$9:$O$88, Pengeluaran!$N$9:$N$88, ">="&'Detail Transaksi'!B51, Pengeluaran!$N$9:$N$88, "<="&'Detail Transaksi'!E51) -> 0 | D13: =SUMIFS(Pengeluaran!G9:G129, Pengeluaran!F9:F129, TODAY(), Pengeluaran!E9:E129, "Tunai") + SUMIFS(Pengeluaran!O9:O88, Pengeluaran!N9:N88, TODAY(), Pengeluaran!M9:M88, "Tunai") -> 0 | E13: ='Detail Transaksi'!D12 -> 0 | F13: ='Detail Transaksi'!R12 -> 0
C15: pengeluaran minggu 5 | D15: pengeluaran total hari ini
C16: =SUMIFS(Pengeluaran!$G$9:$G$129, Pengeluaran!$F$9:$F$129, ">="&'Detail Transaksi'!B52, Pengeluaran!$F$9:$F$129, "<="&'Detail Transaksi'!E52) + SUMIFS(Pengeluaran!$O$9:$O$88, Pengeluaran!$N$9:$N$88, ">="&'Detail Transaksi'!B52, Pengeluaran!$N$9:$N$88, "<="&'Detail Transaksi'!E52) -> 0 | D16: =('Detail Transaksi'!W23+'Detail Transaksi'!W28) -> 0
C18: sisa total uang
C19: =('Detail Transaksi'!D9+'Detail Transaksi'!R9)-SUM('Detail Transaksi'!K8:N17) -> 0
A21: pengeluaran
A22: total makanan dan jajan
A23: =SUM(Pengeluaran!G9:G129) -> 0
A25: total kebutuhan
A26: =SUM(Pengeluaran!O9:O88) -> 0
A28: pendapatan
A29: total pendapatan
A30: =SUMIFS(Pendapatan!G6:G15, Pendapatan!C6:C15, "<>Transisi") -> 0
A32: akhir bulan
A33: heatmap
A34: 1 | B34: 2 | C34: 3 | D34: 4 | E34: 5 | F34: 6 | G34: 7 | H34: tabungan awal | I34: tabungan akhir | J34: perubahan | K34: persentase perubahan
A35: =SUMIFS(Pengeluaran!$G$9:$G$129,Pengeluaran!$F$9:$F$129,'Akhir Bulan'!B9)+ SUMIFS(Pengeluaran!$O$9:$O$88,Pengeluaran!$N$9:$N$88,'Akhir Bulan'!B9) -> 0 | B35: =SUMIFS(Pengeluaran!$G$9:$G$129,Pengeluaran!$F$9:$F$129,'Akhir Bulan'!C9)+ SUMIFS(Pengeluaran!$O$9:$O$88,Pengeluaran!$N$9:$N$88,'Akhir Bulan'!C9) -> 0 | C35: =SUMIFS(Pengeluaran!$G$9:$G$129,Pengeluaran!$F$9:$F$129,'Akhir Bulan'!D9)+ SUMIFS(Pengeluaran!$O$9:$O$88,Pengeluaran!$N$9:$N$88,'Akhir Bulan'!D9) -> 0 | D35: =SUMIFS(Pengeluaran!$G$9:$G$129,Pengeluaran!$F$9:$F$129,'Akhir Bulan'!E9)+ SUMIFS(Pengeluaran!$O$9:$O$88,Pengeluaran!$N$9:$N$88,'Akhir Bulan'!E9) -> 0 | E35: =SUMIFS(Pengeluaran!$G$9:$G$129,Pengeluaran!$F$9:$F$129,'Akhir Bulan'!F9)+ SUMIFS(Pengeluaran!$O$9:$O$88,Pengeluaran!$N$9:$N$88,'Akhir Bulan'!F9) -> 0 | F35: =SUMIFS(Pengeluaran!$G$9:$G$129,Pengeluaran!$F$9:$F$129,'Akhir Bulan'!G9)+ SUMIFS(Pengeluaran!$O$9:$O$88,Pengeluaran!$N$9:$N$88,'Akhir Bulan'!G9) -> 0 | G35: =SUMIFS(Pengeluaran!$G$9:$G$129,Pengeluaran!$F$9:$F$129,'Akhir Bulan'!H9)+ SUMIFS(Pengeluaran!$O$9:$O$88,Pengeluaran!$N$9:$N$88,'Akhir Bulan'!H9) -> 0 | H35: ='Detail Transaksi'!D15+'Detail Transaksi'!R15 -> 0 | I35: =J41+H35 -> 0 | J35: =I35-H35 -> 0 | K35: =IFERROR(J35/H35, 0) -> 0
A37: 8 | B37: 9 | C37: 10 | D37: 11 | E37: 12 | F37: 13 | G37: 14 | H37: hasil tabungan
A38: =SUMIFS(Pengeluaran!$G$9:$G$129, Pengeluaran!$F$9:$F$129, 'Akhir Bulan'!B13)+ SUMIFS(Pengeluaran!$O$9:$O$88,Pengeluaran!$N$9:$N$88,'Akhir Bulan'!B13) -> 0 | B38: =SUMIFS(Pengeluaran!$G$9:$G$129, Pengeluaran!$F$9:$F$129, 'Akhir Bulan'!C13)+ SUMIFS(Pengeluaran!$O$9:$O$88,Pengeluaran!$N$9:$N$88,'Akhir Bulan'!C13) -> 0 | C38: =SUMIFS(Pengeluaran!$G$9:$G$129, Pengeluaran!$F$9:$F$129, 'Akhir Bulan'!D13)+ SUMIFS(Pengeluaran!$O$9:$O$88,Pengeluaran!$N$9:$N$88,'Akhir Bulan'!D13) -> 0 | D38: =SUMIFS(Pengeluaran!$G$9:$G$129, Pengeluaran!$F$9:$F$129, 'Akhir Bulan'!E13)+ SUMIFS(Pengeluaran!$O$9:$O$88,Pengeluaran!$N$9:$N$88,'Akhir Bulan'!E13) -> 0 | E38: =SUMIFS(Pengeluaran!$G$9:$G$129, Pengeluaran!$F$9:$F$129, 'Akhir Bulan'!F13)+ SUMIFS(Pengeluaran!$O$9:$O$88,Pengeluaran!$N$9:$N$88,'Akhir Bulan'!F13) -> 0 | F38: =SUMIFS(Pengeluaran!$G$9:$G$129, Pengeluaran!$F$9:$F$129, 'Akhir Bulan'!G13)+ SUMIFS(Pengeluaran!$O$9:$O$88,Pengeluaran!$N$9:$N$88,'Akhir Bulan'!G13) -> 0 | G38: =SUMIFS(Pengeluaran!$G$9:$G$129, Pengeluaran!$F$9:$F$129, 'Akhir Bulan'!H13)+ SUMIFS(Pengeluaran!$O$9:$O$88,Pengeluaran!$N$9:$N$88,'Akhir Bulan'!H13) -> 0 | H38: =IF(K35>0, "Bertambah 👍", IF(K35<0, "Berkurang 👎", "Tetap 😐")) -> Tetap 😐
A40: 15 | B40: 16 | C40: 17 | D40: 18 | E40: 19 | F40: 20 | G40: 21 | H40: pemasukan | I40: pengeluaran | J40: sisa uang (arus kas bersih) | K40: persentase arus kas
A41: =SUMIFS(Pengeluaran!$G$9:$G$129, Pengeluaran!$F$9:$F$129, 'Akhir Bulan'!B17)+ SUMIFS(Pengeluaran!$O$9:$O$88,Pengeluaran!$N$9:$N$88,'Akhir Bulan'!B17) -> 0 | B41: =SUMIFS(Pengeluaran!$G$9:$G$129, Pengeluaran!$F$9:$F$129, 'Akhir Bulan'!C17)+ SUMIFS(Pengeluaran!$O$9:$O$88,Pengeluaran!$N$9:$N$88,'Akhir Bulan'!C17) -> 0 | C41: =SUMIFS(Pengeluaran!$G$9:$G$129, Pengeluaran!$F$9:$F$129, 'Akhir Bulan'!D17)+ SUMIFS(Pengeluaran!$O$9:$O$88,Pengeluaran!$N$9:$N$88,'Akhir Bulan'!D17) -> 0 | D41: =SUMIFS(Pengeluaran!$G$9:$G$129, Pengeluaran!$F$9:$F$129, 'Akhir Bulan'!E17)+ SUMIFS(Pengeluaran!$O$9:$O$88,Pengeluaran!$N$9:$N$88,'Akhir Bulan'!E17) -> 0 | E41: =SUMIFS(Pengeluaran!$G$9:$G$129, Pengeluaran!$F$9:$F$129, 'Akhir Bulan'!F17)+ SUMIFS(Pengeluaran!$O$9:$O$88,Pengeluaran!$N$9:$N$88,'Akhir Bulan'!F17) -> 0 | F41: =SUMIFS(Pengeluaran!$G$9:$G$129, Pengeluaran!$F$9:$F$129, 'Akhir Bulan'!G17)+ SUMIFS(Pengeluaran!$O$9:$O$88,Pengeluaran!$N$9:$N$88,'Akhir Bulan'!G17) -> 0 | G41: =SUMIFS(Pengeluaran!$G$9:$G$129, Pengeluaran!$F$9:$F$129, 'Akhir Bulan'!H17)+ SUMIFS(Pengeluaran!$O$9:$O$88,Pengeluaran!$N$9:$N$88,'Akhir Bulan'!H17) -> 0 | H41: =SUMIFS(Pendapatan!G6:G15, Pendapatan!C6:C15, "Uang_Bulanan") -> 0 | I41: =Pengeluaran!H9+Pengeluaran!P9 -> 0 | J41: =H41-I41 -> 0 | K41: =IFERROR(J41/H41, 0) -> 0
A43: 22 | B43: 23 | C43: 24 | D43: 25 | E43: 26 | F43: 27 | G43: 28 | H43: hasil arus kas
A44: =SUMIFS(Pengeluaran!$G$9:$G$129, Pengeluaran!$F$9:$F$129, 'Akhir Bulan'!B21)+ SUMIFS(Pengeluaran!$O$9:$O$88,Pengeluaran!$N$9:$N$88,'Akhir Bulan'!B21) -> 0 | B44: =SUMIFS(Pengeluaran!$G$9:$G$129, Pengeluaran!$F$9:$F$129, 'Akhir Bulan'!C21)+ SUMIFS(Pengeluaran!$O$9:$O$88,Pengeluaran!$N$9:$N$88,'Akhir Bulan'!C21) -> 0 | C44: =SUMIFS(Pengeluaran!$G$9:$G$129, Pengeluaran!$F$9:$F$129, 'Akhir Bulan'!D21)+ SUMIFS(Pengeluaran!$O$9:$O$88,Pengeluaran!$N$9:$N$88,'Akhir Bulan'!D21) -> 0 | D44: =SUMIFS(Pengeluaran!$G$9:$G$129, Pengeluaran!$F$9:$F$129, 'Akhir Bulan'!E21)+ SUMIFS(Pengeluaran!$O$9:$O$88,Pengeluaran!$N$9:$N$88,'Akhir Bulan'!E21) -> 0 | E44: =SUMIFS(Pengeluaran!$G$9:$G$129, Pengeluaran!$F$9:$F$129, 'Akhir Bulan'!F21)+ SUMIFS(Pengeluaran!$O$9:$O$88,Pengeluaran!$N$9:$N$88,'Akhir Bulan'!F21) -> 0 | F44: =SUMIFS(Pengeluaran!$G$9:$G$129, Pengeluaran!$F$9:$F$129, 'Akhir Bulan'!G21)+ SUMIFS(Pengeluaran!$O$9:$O$88,Pengeluaran!$N$9:$N$88,'Akhir Bulan'!G21) -> 0 | G44: =SUMIFS(Pengeluaran!$G$9:$G$129, Pengeluaran!$F$9:$F$129, 'Akhir Bulan'!H21)+ SUMIFS(Pengeluaran!$O$9:$O$88,Pengeluaran!$N$9:$N$88,'Akhir Bulan'!H21) -> 0 | H44: =IF(K41>=0, "Positif ✅", "Negatif❗️") -> Positif ✅
A46: 29 | B46: 30 | C46: 31
A47: =SUMIFS(Pengeluaran!$G$9:$G$129, Pengeluaran!$F$9:$F$129, 'Akhir Bulan'!B25)+ SUMIFS(Pengeluaran!$O$9:$O$88,Pengeluaran!$N$9:$N$88,'Akhir Bulan'!B25) -> 0 | B47: =SUMIFS(Pengeluaran!$G$9:$G$129, Pengeluaran!$F$9:$F$129, 'Akhir Bulan'!C25)+ SUMIFS(Pengeluaran!$O$9:$O$88,Pengeluaran!$N$9:$N$88,'Akhir Bulan'!C25) -> 0 | C47: =SUMIFS(Pengeluaran!$G$9:$G$129, Pengeluaran!$F$9:$F$129, 'Akhir Bulan'!D25)+ SUMIFS(Pengeluaran!$O$9:$O$88,Pengeluaran!$N$9:$N$88,'Akhir Bulan'!D25) -> 0
A49: sarapan | C49: makan siang | E49: makan malam | G49: jajan | I49: sahur | K49: buka puasa
A50: warteg | B50: =SUMIFS(Pengeluaran!$G$9:$G$129, Pengeluaran!$C$9:$C$129, 'Akhir Bulan'!$B$32, Pengeluaran!$D$9:$D$129, 'Akhir Bulan'!B34) -> 0 | C50: warteg | D50: =SUMIFS(Pengeluaran!$G$9:$G$129, Pengeluaran!$C$9:$C$129, 'Akhir Bulan'!$E$32, Pengeluaran!$D$9:$D$129, 'Akhir Bulan'!E34) -> 0 | E50: warteg | F50: =SUMIFS(Pengeluaran!$G$9:$G$129, Pengeluaran!$C$9:$C$129, 'Akhir Bulan'!$H$32, Pengeluaran!$D$9:$D$129, 'Akhir Bulan'!H34) -> 0 | G50: keripik/snack | H50: =SUMIFS(Pengeluaran!$G$9:$G$129, Pengeluaran!$C$9:$C$129, 'Akhir Bulan'!$K$32, Pengeluaran!$D$9:$D$129, 'Akhir Bulan'!K34) -> 0 | I50: bikin sendiri | J50: =SUMIFS(Pengeluaran!$G$9:$G$129, Pengeluaran!$C$9:$C$129, 'Akhir Bulan'!$N$32, Pengeluaran!$D$9:$D$129, 'Akhir Bulan'!N34) -> 0 | K50: warteg | L50: =SUMIFS(Pengeluaran!$G$9:$G$129, Pengeluaran!$C$9:$C$129, 'Akhir Bulan'!$Q$32, Pengeluaran!$D$9:$D$129, 'Akhir Bulan'!Q34) -> 0
A51: bikin sendiri | B51: =SUMIFS(Pengeluaran!$G$9:$G$129, Pengeluaran!$C$9:$C$129, 'Akhir Bulan'!$B$32, Pengeluaran!$D$9:$D$129, 'Akhir Bulan'!B36) -> 0 | C51: bikin sendiri | D51: =SUMIFS(Pengeluaran!$G$9:$G$129, Pengeluaran!$C$9:$C$129, 'Akhir Bulan'!$E$32, Pengeluaran!$D$9:$D$129, 'Akhir Bulan'!E36) -> 0 | E51: bikin sendiri | F51: =SUMIFS(Pengeluaran!$G$9:$G$129, Pengeluaran!$C$9:$C$129, 'Akhir Bulan'!$H$32, Pengeluaran!$D$9:$D$129, 'Akhir Bulan'!H36) -> 0 | G51: minuman manis | H51: =SUMIFS(Pengeluaran!$G$9:$G$129, Pengeluaran!$C$9:$C$129, 'Akhir Bulan'!$K$32, Pengeluaran!$D$9:$D$129, 'Akhir Bulan'!K36) -> 0 | I51: sate | J51: =SUMIFS(Pengeluaran!$G$9:$G$129, Pengeluaran!$C$9:$C$129, 'Akhir Bulan'!$N$32, Pengeluaran!$D$9:$D$129, 'Akhir Bulan'!N36) -> 0 | K51: bikin sendiri | L51: =SUMIFS(Pengeluaran!$G$9:$G$129, Pengeluaran!$C$9:$C$129, 'Akhir Bulan'!$Q$32, Pengeluaran!$D$9:$D$129, 'Akhir Bulan'!Q36) -> 0
A52: nasi kuning | B52: =SUMIFS(Pengeluaran!$G$9:$G$129, Pengeluaran!$C$9:$C$129, 'Akhir Bulan'!$B$32, Pengeluaran!$D$9:$D$129, 'Akhir Bulan'!B38) -> 0 | C52: fkg | D52: =SUMIFS(Pengeluaran!$G$9:$G$129, Pengeluaran!$C$9:$C$129, 'Akhir Bulan'!$E$32, Pengeluaran!$D$9:$D$129, 'Akhir Bulan'!E38) -> 0 | E52: nasi goreng | F52: =SUMIFS(Pengeluaran!$G$9:$G$129, Pengeluaran!$C$9:$C$129, 'Akhir Bulan'!$H$32, Pengeluaran!$D$9:$D$129, 'Akhir Bulan'!H38) -> 0 | G52: es krim | H52: =SUMIFS(Pengeluaran!$G$9:$G$129, Pengeluaran!$C$9:$C$129, 'Akhir Bulan'!$K$32, Pengeluaran!$D$9:$D$129, 'Akhir Bulan'!K38) -> 0 | K52: beli | L52: =SUMIFS(Pengeluaran!$G$9:$G$129, Pengeluaran!$C$9:$C$129, 'Akhir Bulan'!$Q$32, Pengeluaran!$D$9:$D$129, 'Akhir Bulan'!Q38) -> 0
A53: nasi uduk | B53: =SUMIFS(Pengeluaran!$G$9:$G$129, Pengeluaran!$C$9:$C$129, 'Akhir Bulan'!$B$32, Pengeluaran!$D$9:$D$129, 'Akhir Bulan'!B40) -> 0 | C53: balsan | D53: =SUMIFS(Pengeluaran!$G$9:$G$129, Pengeluaran!$C$9:$C$129, 'Akhir Bulan'!$E$32, Pengeluaran!$D$9:$D$129, 'Akhir Bulan'!E40) -> 0 | E53: kwetiauw goreng | F53: =SUMIFS(Pengeluaran!$G$9:$G$129, Pengeluaran!$C$9:$C$129, 'Akhir Bulan'!$H$32, Pengeluaran!$D$9:$D$129, 'Akhir Bulan'!H40) -> 0 | G53: biskuit | H53: =SUMIFS(Pengeluaran!$G$9:$G$129, Pengeluaran!$C$9:$C$129, 'Akhir Bulan'!$K$32, Pengeluaran!$D$9:$D$129, 'Akhir Bulan'!K40) -> 0
A54: gofood | B54: =SUMIFS(Pengeluaran!$G$9:$G$129, Pengeluaran!$C$9:$C$129, 'Akhir Bulan'!$B$32, Pengeluaran!$D$9:$D$129, 'Akhir Bulan'!B42) -> 0 | C54: gofood | D54: =SUMIFS(Pengeluaran!$G$9:$G$129, Pengeluaran!$C$9:$C$129, 'Akhir Bulan'!$E$32, Pengeluaran!$D$9:$D$129, 'Akhir Bulan'!E42) -> 0 | E54: gofood | F54: =SUMIFS(Pengeluaran!$G$9:$G$129, Pengeluaran!$C$9:$C$129, 'Akhir Bulan'!$H$32, Pengeluaran!$D$9:$D$129, 'Akhir Bulan'!H42) -> 0 | G54: cokelat | H54: =SUMIFS(Pengeluaran!$G$9:$G$129, Pengeluaran!$C$9:$C$129, 'Akhir Bulan'!$K$32, Pengeluaran!$D$9:$D$129, 'Akhir Bulan'!K42) -> 0
...
